<?xml version="1.0"?>
<robot name="gazebo_robot">

  <material name="blue">
    <color rgba="0.2 0.5 0.8 1.0"/>
  </material>
  <material name="black">
    <color rgba="0.1 0.1 0.1 1.0"/>
  </material>
  <material name="white">
    <color rgba="0.9 0.9 0.9 1.0"/>
  </material>
  <material name="red">
    <color rgba="0.8 0.2 0.2 1.0"/>
  </material>
  <material name="gray">
    <color rgba="0.5 0.5 0.5 1.0"/>
  </material>

  <link name="base_link">
    <visual>
      <geometry>
        <box size="0.5 0.35 0.15"/>
      </geometry>
      <material name="blue"/>
    </visual>
    <collision>
      <geometry>
        <box size="0.5 0.35 0.15"/>
      </geometry>
    </collision>
    <inertial>
      <mass value="10.0"/>
      <inertia ixx="0.1" ixy="0.0" ixz="0.0"
               iyy="0.1" iyz="0.0"
               izz="0.1"/>
    </inertial>
  </link>

  <joint name="base_joint" type="fixed">
    <parent link="base_link"/>
    <child link="chassis"/>
    <origin xyz="0 0 -0.075" rpy="0 0 0"/>
  </joint>

  <link name="chassis">
    <visual>
      <geometry>
        <box size="0.5 0.35 0.05"/>
      </geometry>
      <material name="gray"/>
    </visual>
    <collision>
      <geometry>
        <box size="0.5 0.35 0.05"/>
      </geometry>
    </collision>
    <inertial>
      <mass value="1.0"/>
      <inertia ixx="0.01" ixy="0.0" ixz="0.0"
               iyy="0.01" iyz="0.0"
               izz="0.01"/>
    </inertial>
  </link>

  <link name="left_wheel">
    <visual>
      <geometry>
        <cylinder radius="0.05" length="0.04"/>
      </geometry>
      <material name="black"/>
    </visual>
    <collision>
      <geometry>
        <cylinder radius="0.05" length="0.04"/>
      </geometry>
    </collision>
    <inertial>
      <mass value="1.0"/>
      <inertia ixx="0.001" ixy="0.0" ixz="0.0"
               iyy="0.001" iyz="0.0"
               izz="0.001"/>
    </inertial>
  </link>

  <joint name="left_wheel_joint" type="continuous">
    <parent link="base_link"/>
    <child link="left_wheel"/>
    <origin xyz="0.0 0.2 -0.05" rpy="1.5708 0 0"/>
    <axis xyz="0 0 1"/>
    <limit effort="10" velocity="10"/>
  </joint>

  <link name="right_wheel">
    <visual>
      <geometry>
        <cylinder radius="0.05" length="0.04"/>
      </geometry>
      <material name="black"/>
    </visual>
    <collision>
      <geometry>
        <cylinder radius="0.05" length="0.04"/>
      </geometry>
    </collision>
    <inertial>
      <mass value="1.0"/>
      <inertia ixx="0.001" ixy="0.0" ixz="0.0"
               iyy="0.001" iyz="0.0"
               izz="0.001"/>
    </inertial>
  </link>

  <joint name="right_wheel_joint" type="continuous">
    <parent link="base_link"/>
    <child link="right_wheel"/>
    <origin xyz="0.0 -0.2 -0.05" rpy="1.5708 0 0"/>
    <axis xyz="0 0 1"/>
    <limit effort="10" velocity="10"/>
  </joint>

  <link name="caster_wheel">
    <visual>
      <geometry>
        <sphere radius="0.025"/>
      </geometry>
      <material name="gray"/>
    </visual>
    <collision>
      <geometry>
        <sphere radius="0.025"/>
      </geometry>
    </collision>
    <inertial>
      <mass value="0.5"/>
      <inertia ixx="0.0001" ixy="0.0" ixz="0.0"
               iyy="0.0001" iyz="0.0"
               izz="0.0001"/>
    </inertial>
  </link>

  <joint name="caster_joint" type="fixed">
    <parent link="base_link"/>
    <child link="caster_wheel"/>
    <origin xyz="0.2 0 -0.1" rpy="0 0 0"/>
  </joint>

  <link name="head">
    <visual>
      <geometry>
        <sphere radius="0.08"/>
      </geometry>
      <material name="white"/>
    </visual>
    <collision>
      <geometry>
        <sphere radius="0.08"/>
      </geometry>
    </collision>
    <inertial>
      <mass value="0.5"/>
      <inertia ixx="0.001" ixy="0.0" ixz="0.0"
               iyy="0.001" iyz="0.0"
               izz="0.001"/>
    </inertial>
  </link>

  <joint name="head_joint" type="fixed">
    <parent link="base_link"/>
    <child link="head"/>
    <origin xyz="0.2 0 0.15" rpy="0 0 0"/>
  </joint>

  <link name="left_eye">
    <visual>
      <geometry>
        <sphere radius="0.02"/>
      </geometry>
      <material name="red"/>
    </visual>
  </link>

  <joint name="left_eye_joint" type="fixed">
    <parent link="head"/>
    <child link="left_eye"/>
    <origin xyz="0.05 0.03 0.02" rpy="0 0 0"/>
  </joint>

  <link name="right_eye">
    <visual>
      <geometry>
        <sphere radius="0.02"/>
      </geometry>
      <material name="red"/>
    </visual>
  </link>

  <joint name="right_eye_joint" type="fixed">
    <parent link="head"/>
    <child link="right_eye"/>
    <origin xyz="0.05 -0.03 0.02" rpy="0 0 0"/>
  </joint>

  <link name="camera_mount">
    <visual>
      <geometry>
        <box size="0.1 0.1 0.05"/>
      </geometry>
      <material name="black"/>
    </visual>
    <collision>
      <geometry>
        <box size="0.1 0.1 0.05"/>
      </geometry>
    </collision>
    <inertial>
      <mass value="0.3"/>
      <inertia ixx="0.0001" ixy="0.0" ixz="0.0"
               iyy="0.0001" iyz="0.0"
               izz="0.0001"/>
    </inertial>
  </link>

  <joint name="camera_mount_joint" type="fixed">
    <parent link="base_link"/>
    <child link="camera_mount"/>
    <origin xyz="0.15 0 0.05" rpy="0 0.1745 0"/>
  </joint>

  <link name="camera_color_link">
    <visual>
      <geometry>
        <box size="0.03 0.08 0.02"/>
      </geometry>
      <material name="black"/>
    </visual>
  </link>

  <joint name="camera_color_joint" type="fixed">
    <parent link="camera_mount"/>
    <child link="camera_color_link"/>
    <origin xyz="0.02 0.02 0" rpy="0 0 0"/>
  </joint>

  <link name="camera_depth_link">
    <visual>
      <geometry>
        <box size="0.03 0.08 0.02"/>
      </geometry>
      <material name="black"/>
    </visual>
  </link>

  <joint name="camera_depth_joint" type="fixed">
    <parent link="camera_mount"/>
    <child link="camera_depth_link"/>
    <origin xyz="0.02 -0.02 0" rpy="0 0 0"/>
  </joint>

  <!-- Gazebo plugins -->
  <gazebo>
    <plugin name="differential_drive" filename="libgazebo_ros_diff_drive.so">
      <updateRate>50</updateRate>
      <leftJoint>left_wheel_joint</leftJoint>
      <rightJoint>right_wheel_joint</rightJoint>
      <wheelSeparation>0.4</wheelSeparation>
      <wheelDiameter>0.1</wheelDiameter>
      <maxWheelTorque>20</maxWheelTorque>
      <maxWheelAcceleration>1.0</maxWheelAcceleration>
      <publishOdom>true</publishOdom>
      <publishOdomTF>true</publishOdomTF>
      <publishWheelTF>false</publishWheelTF>
      <odometrySource>world</odometrySource>
      <commandTopic>cmd_vel</commandTopic>
      <odometryTopic>odom</odometryTopic>
      <robotBaseFrame>base_link</robotBaseFrame>
      <odometryFrame>odom</odometryFrame>
      <covariance_x>0.001</covariance_x>
      <covariance_y>0.001</covariance_y>
      <covariance_yaw>0.001</covariance_yaw>
    </plugin>
  </gazebo>

  <gazebo reference="camera_color_link">
    <sensor name="camera_color" type="camera">
      <camera>
        <horizontal_fov>1.047</horizontal_fov>
        <image>
          <width>640</width>
          <height>480</height>
          <format>R8G8B8</format>
        </image>
        <clip>
          <near>0.05</near>
          <far>10</far>
        </clip>
      </camera>
      <always_on>1</always_on>
      <update_rate>30</update_rate>
      <visualize>true</visualize>
      <plugin name="camera_color_controller" filename="libgazebo_ros_camera.so">
        <cameraName>camera_color</cameraName>
        <imageTopicName>camera/color/image_raw</imageTopicName>
        <cameraInfoTopicName>camera/color/camera_info</cameraInfoTopicName>
        <frameName>camera_color_link</frameName>
      </plugin>
    </sensor>
  </gazebo>

  <gazebo reference="camera_depth_link">
    <sensor name="camera_depth" type="depth">
      <camera>
        <horizontal_fov>1.047</horizontal_fov>
        <image>
          <width>640</width>
          <height>480</height>
          <format>R8G8B8</format>
        </image>
        <clip>
          <near>0.05</near>
          <far>10</far>
        </clip>
      </camera>
      <always_on>1</always_on>
      <update_rate>30</update_rate>
      <visualize>true</visualize>
      <plugin name="camera_depth_controller" filename="libgazebo_ros_camera.so">
        <cameraName>camera_depth</cameraName>
        <imageTopicName>camera/depth/image_raw</imageTopicName>
        <cameraInfoTopicName>camera/depth/camera_info</cameraInfoTopicName>
        <pointCloudTopicName>camera/depth/color/points</pointCloudTopicName>
        <frameName>camera_depth_link</frameName>
        <hackBaseline>0.07</hackBaseline>
      </plugin>
    </sensor>
  </gazebo>

  <gazebo reference="left_wheel">
    <mu1>0.9</mu1>
    <mu2>0.9</mu2>
    <kp>1000000.0</kp>
    <kd>1.0</kd>
    <minDepth>0.001</minDepth>
    <maxVel>1.0</maxVel>
    <fdir1>1 0 0</fdir1>
  </gazebo>

  <gazebo reference="right_wheel">
    <mu1>0.9</mu1>
    <mu2>0.9</mu2>
    <kp>1000000.0</kp>
    <kd>1.0</kd>
    <minDepth>0.001</minDepth>
    <maxVel>1.0</maxVel>
    <fdir1>1 0 0</fdir1>
  </gazebo>

  <gazebo reference="caster_wheel">
    <mu1>0.01</mu1>
    <mu2>0.01</mu2>
  </gazebo>

</robot>
